Workbook
Name Slicer_Category: #N/A
Name Slicer_order_year: #N/A
Name Slicer_Region: #N/A
Name Slicer_Segment: #N/A

Sheet Sample - Superstore
A1: Row ID | B1: Order ID | C1: Order Date | D1: Ship Date | E1: Ship Mode | F1: Customer ID | G1: Customer Name | H1: Segment | I1: Country | J1: City | K1: State | L1: Postal Code | M1: Region | N1: Product ID | O1: Category | P1: Sub-Category | Q1: Product Name | R1: Sales | S1: Quantity | T1: Discount | U1: Profit | V1: order month | W1: order year
A2: 1 | B2: CA-2016-152156 | C2: 42682 | D2: 42685 | E2: Second Class | F2: CG-12520 | G2: Claire Gute | H2: Consumer | I2: United States | J2: Henderson | K2: Kentucky | L2: 42420 | M2: South | N2: FUR-BO-10001798 | O2: Furniture | P2: Bookcases | Q2: Bush Somerset Collection Bookcase | R2: 261.96 | S2: 2 | T2: 0 | U2: 41.9136 | V2: =EOMONTH(C2,0) -> 42704 | W2: =YEAR(C2) -> 2016
A3: 2 | B3: CA-2016-152156 | C3: 42682 | D3: 42685 | E3: Second Class | F3: CG-12520 | G3: Claire Gute | H3: Consumer | I3: United States | J3: Henderson | K3: Kentucky | L3: 42420 | M3: South | N3: FUR-CH-10000454 | O3: Furniture | P3: Chairs | Q3: Hon Deluxe Fabric Upholstered Stacking Chairs, Rounded Back | R3: 731.94 | S3: 3 | T3: 0 | U3: 219.582 | V3: =EOMONTH(C3,0) -> 42704 | W3: =YEAR(C3) -> 2016
A4: 3 | B4: CA-2016-138688 | C4: 42533 | D4: 6/16/2016 | E4: Second Class | F4: DV-13045 | G4: Darrin Van Huff | H4: Corporate | I4: United States | J4: Los Angeles | K4: California | L4: 90036 | M4: West | N4: OFF-LA-10000240 | O4: Office Supplies | P4: Labels | Q4: Self-Adhesive Address Labels for Typewriters by Universal | R4: 14.62 | S4: 2 | T4: 0 | U4: 6.8714 | V4: =EOMONTH(C4,0) -> 42551 | W4: =YEAR(C4) -> 2016
A5: 4 | B5: US-2015-108966 | C5: 42288 | D5: 10/18/2015 | E5: Standard Class | F5: SO-20335 | G5: Sean O'Donnell | H5: Consumer | I5: United States | J5: Fort Lauderdale | K5: Florida | L5: 33311 | M5: South | N5: FUR-TA-10000577 | O5: Furniture | P5: Tables | Q5: Bretford CR4500 Series Slim Rectangular Table | R5: 957.5775 | S5: 5 | T5: 0.45 | U5: -383.031 | V5: =EOMONTH(C5,0) -> 42308 | W5: =YEAR(C5) -> 2015
A6: 5 | B6: US-2015-108966 | C6: 42288 | D6: 10/18/2015 | E6: Standard Class | F6: SO-20335 | G6: Sean O'Donnell | H6: Consumer | I6: United States | J6: Fort Lauderdale | K6: Florida | L6: 33311 | M6: South | N6: OFF-ST-10000760 | O6: Office Supplies | P6: Storage | Q6: Eldon Fold 'N Roll Cart System | R6: 22.368 | S6: 2 | T6: 0.2 | U6: 2.5164 | V6: =EOMONTH(C6,0) -> 42308 | W6: =YEAR(C6) -> 2015
A7: 6 | B7: CA-2014-115812 | C7: 41799 | D7: 6/14/2014 | E7: Standard Class | F7: BH-11710 | G7: Brosina Hoffman | H7: Consumer | I7: United States | J7: Los Angeles | K7: California | L7: 90032 | M7: West | N7: FUR-FU-10001487 | O7: Furniture | P7: Furnishings | Q7: Eldon Expressions Wood and Plastic Desk Accessories, Cherry Wood | R7: 48.86 | S7: 7 | T7: 0 | U7: 14.1694 | V7: =EOMONTH(C7,0) -> 41820 | W7: =YEAR(C7) -> 2014
A8: 7 | B8: CA-2014-115812 | C8: 41799 | D8: 6/14/2014 | E8: Standard Class | F8: BH-11710 | G8: Brosina Hoffman | H8: Consumer | I8: United States | J8: Los Angeles | K8: California | L8: 90032 | M8: West | N8: OFF-AR-10002833 | O8: Office Supplies | P8: Art | Q8: Newell 322 | R8: 7.28 | S8: 4 | T8: 0 | U8: 1.9656 | V8: =EOMONTH(C8,0) -> 41820 | W8: =YEAR(C8) -> 2014
A9: 8 | B9: CA-2014-115812 | C9: 41799 | D9: 6/14/2014 | E9: Standard Class | F9: BH-11710 | G9: Brosina Hoffman | H9: Consumer | I9: United States | J9: Los Angeles | K9: California | L9: 90032 | M9: West | N9: TEC-PH-10002275 | O9: Technology | P9: Phones | Q9: Mitel 5320 IP Phone VoIP phone | R9: 907.152 | S9: 6 | T9: 0.2 | U9: 90.7152 | V9: =EOMONTH(C9,0) -> 41820 | W9: =YEAR(C9) -> 2014
A10: 9 | B10: CA-2014-115812 | C10: 41799 | D10: 6/14/2014 | E10: Standard Class | F10: BH-11710 | G10: Brosina Hoffman | H10: Consumer | I10: United States | J10: Los Angeles | K10: California | L10: 90032 | M10: West | N10: OFF-BI-10003910 | O10: Office Supplies | P10: Binders | Q10: DXL Angle-View Binders with Locking Rings by Samsill | R10: 18.504 | S10: 3 | T10: 0.2 | U10: 5.7825 | V10: =EOMONTH(C10,0) -> 41820 | W10: =YEAR(C10) -> 2014
A11: 10 | B11: CA-2014-115812 | C11: 41799 | D11: 6/14/2014 | E11: Standard Class | F11: BH-11710 | G11: Brosina Hoffman | H11: Consumer | I11: United States | J11: Los Angeles | K11: California | L11: 90032 | M11: West | N11: OFF-AP-10002892 | O11: Office Supplies | P11: Appliances | Q11: Belkin F5C206VTEL 6 Outlet Surge | R11: 114.9 | S11: 5 | T11: 0 | U11: 34.47 | V11: =EOMONTH(C11,0) -> 41820 | W11: =YEAR(C11) -> 2014
A12: 11 | B12: CA-2014-115812 | C12: 41799 | D12: 6/14/2014 | E12: Standard Class | F12: BH-11710 | G12: Brosina Hoffman | H12: Consumer | I12: United States | J12: Los Angeles | K12: California | L12: 90032 | M12: West | N12: FUR-TA-10001539 | O12: Furniture | P12: Tables | Q12: Chromcraft Rectangular Conference Tables | R12: 1706.184 | S12: 9 | T12: 0.2 | U12: 85.3092 | V12: =EOMONTH(C12,0) -> 41820 | W12: =YEAR(C12) -> 2014
A13: 12 | B13: CA-2014-115812 | C13: 41799 | D13: 6/14/2014 | E13: Standard Class | F13: BH-11710 | G13: Brosina Hoffman | H13: Consumer | I13: United States | J13: Los Angeles | K13: California | L13: 90032 | M13: West | N13: TEC-PH-10002033 | O13: Technology | P13: Phones | Q13: Konftel 250 Conference†phone†- Charcoal black | R13: 911.424 | S13: 4 | T13: 0.2 | U13: 68.3568 | V13: =EOMONTH(C13,0) -> 41820 | W13: =YEAR(C13) -> 2014
A14: 13 | B14: CA-2017-114412 | C14: 42840 | D14: 4/20/2017 | E14: Standard Class | F14: AA-10480 | G14: Andrew Allen | H14: Consumer | I14: United States | J14: Concord | K14: North Carolina | L14: 28027 | M14: South | N14: OFF-PA-10002365 | O14: Office Supplies | P14: Paper | Q14: Xerox 1967 | R14: 15.552 | S14: 3 | T14: 0.2 | U14: 5.4432 | V14: =EOMONTH(C14,0) -> 42855 | W14: =YEAR(C14) -> 2017
A15: 14 | B15: CA-2016-161389 | C15: 42709 | D15: 42655 | E15: Standard Class | F15: IM-15070 | G15: Irene Maddox | H15: Consumer | I15: United States | J15: Seattle | K15: Washington | L15: 98103 | M15: West | N15: OFF-BI-10003656 | O15: Office Supplies | P15: Binders | Q15: Fellowes PB200 Plastic Comb Binding Machine | R15: 407.976 | S15: 3 | T15: 0.2 | U15: 132.5922 | V15: =EOMONTH(C15,0) -> 42735 | W15: =YEAR(C15) -> 2016
A16: 15 | B16: US-2015-118983 | C16: 42330 | D16: 11/26/2015 | E16: Standard Class | F16: HP-14815 | G16: Harold Pawlan | H16: Home Office | I16: United States | J16: Fort Worth | K16: Texas | L16: 76106 | M16: Central | N16: OFF-AP-10002311 | O16: Office Supplies | P16: Appliances | Q16: Holmes Replacement Filter for HEPA Air Cleaner, Very Large Room, HEPA Filter | R16: 68.81 | S16: 5 | T16: 0.8 | U16: -123.858 | V16: =EOMONTH(C16,0) -> 42338 | W16: =YEAR(C16) -> 2015
A17: 16 | B17: US-2015-118983 | C17: 42330 | D17: 11/26/2015 | E17: Standard Class | F17: HP-14815 | G17: Harold Pawlan | H17: Home Office | I17: United States | J17: Fort Worth | K17: Texas | L17: 76106 | M17: Central | N17: OFF-BI-10000756 | O17: Office Supplies | P17: Binders | Q17: Storex DuraTech Recycled Plastic Frosted Binders | R17: 2.544 | S17: 3 | T17: 0.8 | U17: -3.816 | V17: =EOMONTH(C17,0) -> 42338 | W17: =YEAR(C17) -> 2015
A18: 17 | B18: CA-2014-105893 | C18: 41954 | D18: 11/18/2014 | E18: Standard Class | F18: PK-19075 | G18: Pete Kriz | H18: Consumer | I18: United States | J18: Madison | K18: Wisconsin | L18: 53711 | M18: Central | N18: OFF-ST-10004186 | O18: Office Supplies | P18: Storage | Q18: Stur-D-Stor Shelving, Vertical 5-Shelf: 72"H x 36"W x 18 1/2"D | R18: 665.88 | S18: 6 | T18: 0 | U18: 13.3176 | V18: =EOMONTH(C18,0) -> 41973 | W18: =YEAR(C18) -> 2014
A19: 18 | B19: CA-2014-167164 | C19: 41772 | D19: 5/15/2014 | E19: Second Class | F19: AG-10270 | G19: Alejandro Grove | H19: Consumer | I19: United States | J19: West Jordan | K19: Utah | L19: 84084 | M19: West | N19: OFF-ST-10000107 | O19: Office Supplies | P19: Storage | Q19: Fellowes Super Stor/Drawer | R19: 55.5 | S19: 2 | T19: 0 | U19: 9.99 | V19: =EOMONTH(C19,0) -> 41790 | W19: =YEAR(C19) -> 2014
A20: 19 | B20: CA-2014-143336 | C20: 41878 | D20: 41648 | E20: Second Class | F20: ZD-21925 | G20: Zuschuss Donatelli | H20: Consumer | I20: United States | J20: San Francisco | K20: California | L20: 94109 | M20: West | N20: OFF-AR-10003056 | O20: Office Supplies | P20: Art | Q20: Newell 341 | R20: 8.56 | S20: 2 | T20: 0 | U20: 2.4824 | V20: =EOMONTH(C20,0) -> 41882 | W20: =YEAR(C20) -> 2014
A21: 20 | B21: CA-2014-143336 | C21: 41878 | D21: 41648 | E21: Second Class | F21: ZD-21925 | G21: Zuschuss Donatelli | H21: Consumer | I21: United States | J21: San Francisco | K21: California | L21: 94109 | M21: West | N21: TEC-PH-10001949 | O21: Technology | P21: Phones | Q21: Cisco SPA 501G IP Phone | R21: 213.48 | S21: 3 | T21: 0.2 | U21: 16.011 | V21: =EOMONTH(C21,0) -> 41882 | W21: =YEAR(C21) -> 2014
A22: 21 | B22: CA-2014-143336 | C22: 41878 | D22: 41648 | E22: Second Class | F22: ZD-21925 | G22: Zuschuss Donatelli | H22: Consumer | I22: United States | J22: San Francisco | K22: California | L22: 94109 | M22: West | N22: OFF-BI-10002215 | O22: Office Supplies | P22: Binders | Q22: Wilson Jones Hanging View Binder, White, 1" | R22: 22.72 | S22: 4 | T22: 0.2 | U22: 7.384 | V22: =EOMONTH(C22,0) -> 41882 | W22: =YEAR(C22) -> 2014
A23: 22 | B23: CA-2016-137330 | C23: 42713 | D23: 12/13/2016 | E23: Standard Class | F23: KB-16585 | G23: Ken Black | H23: Corporate | I23: United States | J23: Fremont | K23: Nebraska | L23: 68025 | M23: Central | N23: OFF-AR-10000246 | O23: Office Supplies | P23: Art | Q23: Newell 318 | R23: 19.46 | S23: 7 | T23: 0 | U23: 5.0596 | V23: =EOMONTH(C23,0) -> 42735 | W23: =YEAR(C23) -> 2016
A24: 23 | B24: CA-2016-137330 | C24: 42713 | D24: 12/13/2016 | E24: Standard Class | F24: KB-16585 | G24: Ken Black | H24: Corporate | I24: United States | J24: Fremont | K24: Nebraska | L24: 68025 | M24: Central | N24: OFF-AP-10001492 | O24: Office Supplies | P24: Appliances | Q24: Acco Six-Outlet Power Strip, 4' Cord Length | R24: 60.34 | S24: 7 | T24: 0 | U24: 15.6884 | V24: =EOMONTH(C24,0) -> 42735 | W24: =YEAR(C24) -> 2016
A25: 24 | B25: US-2017-156909 | C25: 42932 | D25: 7/18/2017 | E25: Second Class | F25: SF-20065 | G25: Sandra Flanagan | H25: Consumer | I25: United States | J25: Philadelphia | K25: Pennsylvania | L25: 19140 | M25: East | N25: FUR-CH-10002774 | O25: Furniture | P25: Chairs | Q25: Global Deluxe Stacking Chair, Gray | R25: 71.372 | S25: 2 | T25: 0.3 | U25: -1.0196 | V25: =EOMONTH(C25,0) -> 42947 | W25: =YEAR(C25) -> 2017
A26: 25 | B26: CA-2015-106320 | C26: 42272 | D26: 9/30/2015 | E26: Standard Class | F26: EB-13870 | G26: Emily Burns | H26: Consumer | I26: United States | J26: Orem | K26: Utah | L26: 84057 | M26: West | N26: FUR-TA-10000577 | O26: Furniture | P26: Tables | Q26: Bretford CR4500 Series Slim Rectangular Table | R26: 1044.63 | S26: 3 | T26: 0 | U26: 240.2649 | V26: =EOMONTH(C26,0) -> 42277 | W26: =YEAR(C26) -> 2015
A27: 26 | B27: CA-2016-121755 | C27: 42385 | D27: 1/20/2016 | E27: Second Class | F27: EH-13945 | G27: Eric Hoffmann | H27: Consumer | I27: United States | J27: Los Angeles | K27: California | L27: 90049 | M27: West | N27: OFF-BI-10001634 | O27: Office Supplies | P27: Binders | Q27: Wilson Jones Active Use Binders | R27: 11.648 | S27: 2 | T27: 0.2 | U27: 4.2224 | V27: =EOMONTH(C27,0) -> 42400 | W27: =YEAR(C27) -> 2016
A28: 27 | B28: CA-2016-121755 | C28: 42385 | D28: 1/20/2016 | E28: Second Class | F28: EH-13945 | G28: Eric Hoffmann | H28: Consumer | I28: United States | J28: Los Angeles | K28: California | L28: 90049 | M28: West | N28: TEC-AC-10003027 | O28: Technology | P28: Accessories | Q28: Imation†8GB Mini TravelDrive USB 2.0†Flash Drive | R28: 90.57 | S28: 3 | T28: 0 | U28: 11.7741 | V28: =EOMONTH(C28,0) -> 42400 | W28: =YEAR(C28) -> 2016
A29: 28 | B29: US-2015-150630 | C29: 42264 | D29: 9/21/2015 | E29: Standard Class | F29: TB-21520 | G29: Tracy Blumstein | H29: Consumer | I29: United States | J29: Philadelphia | K29: Pennsylvania | L29: 19140 | M29: East | N29: FUR-BO-10004834 | O29: Furniture | P29: Bookcases | Q29: Riverside Palais Royal Lawyers Bookcase, Royale Cherry Finish | R29: 3083.43 | S29: 7 | T29: 0.5 | U29: -1665.0522 | V29: =EOMONTH(C29,0) -> 42277 | W29: =YEAR(C29) -> 2015
A30: 29 | B30: US-2015-150630 | C30: 42264 | D30: 9/21/2015 | E30: Standard Class | F30: TB-21520 | G30: Tracy Blumstein | H30: Consumer | I30: United States | J30: Philadelphia | K30: Pennsylvania | L30: 19140 | M30: East | N30: OFF-BI-10000474 | O30: Office Supplies | P30: Binders | Q30: Avery Recycled Flexi-View Covers for Binding Systems | R30: 9.618 | S30: 2 | T30: 0.7 | U30: -7.0532 | V30: =EOMONTH(C30,0) -> 42277 | W30: =YEAR(C30) -> 2015
A31: 30 | B31: US-2015-150630 | C31: 42264 | D31: 9/21/2015 | E31: Standard Class | F31: TB-21520 | G31: Tracy Blumstein | H31: Consumer | I31: United States | J31: Philadelphia | K31: Pennsylvania | L31: 19140 | M31: East | N31: FUR-FU-10004848 | O31: Furniture | P31: Furnishings | Q31: Howard Miller 13-3/4" Diameter Brushed Chrome Round Wall Clock | R31: 124.2 | S31: 3 | T31: 0.2 | U31: 15.525 | V31: =EOMONTH(C31,0) -> 42277 | W31: =YEAR(C31) -> 2015
A32: 31 | B32: US-2015-150630 | C32: 42264 | D32: 9/21/2015 | E32: Standard Class | F32: TB-21520 | G32: Tracy Blumstein | H32: Consumer | I32: United States | J32: Philadelphia | K32: Pennsylvania | L32: 19140 | M32: East | N32: OFF-EN-10001509 | O32: Office Supplies | P32: Envelopes | Q32: Poly String Tie Envelopes | R32: 3.264 | S32: 2 | T32: 0.2 | U32: 1.1016 | V32: =EOMONTH(C32,0) -> 42277 | W32: =YEAR(C32) -> 2015
A33: 32 | B33: US-2015-150630 | C33: 42264 | D33: 9/21/2015 | E33: Standard Class | F33: TB-21520 | G33: Tracy Blumstein | H33: Consumer | I33: United States | J33: Philadelphia | K33: Pennsylvania | L33: 19140 | M33: East | N33: OFF-AR-10004042 | O33: Office Supplies | P33: Art | Q33: BOSTON Model 1800 Electric Pencil Sharpeners, Putty/Woodgrain | R33: 86.304 | S33: 6 | T33: 0.2 | U33: 9.7092 | V33: =EOMONTH(C33,0) -> 42277 | W33: =YEAR(C33) -> 2015
A34: 33 | B34: US-2015-150630 | C34: 42264 | D34: 9/21/2015 | E34: Standard Class | F34: TB-21520 | G34: Tracy Blumstein | H34: Consumer | I34: United States | J34: Philadelphia | K34: Pennsylvania | L34: 19140 | M34: East | N34: OFF-BI-10001525 | O34: Office Supplies | P34: Binders | Q34: Acco Pressboard Covers with Storage Hooks, 14 7/8" x 11", Executive Red | R34: 6.858 | S34: 6 | T34: 0.7 | U34: -5.715 | V34: =EOMONTH(C34,0) -> 42277 | W34: =YEAR(C34) -> 2015
... A36: 35 | B36: CA-2017-107727 | C36: 43027 | D36: 10/23/2017 | E36: Second Class | F36: MA-17560 | G36: Matt Abelman | H36: Home Office | I36: United States | J36: Houston | K36: Texas | L36: 77095 | M36: Central | N36: OFF-PA-10000249 | O36: Office Supplies | P36: Paper | Q36: Easy-staple paper | R36: 29.472 | S36: 3 | T36: 0.2 | U36: 9.9468 | V36: =EOMONTH(C36,0) -> 43039 | W36: =YEAR(C36) -> 2017
A37: 36 | B37: CA-2016-117590 | C37: 42712 | D37: 42655 | E37: First Class | F37: GH-14485 | G37: Gene Hale | H37: Corporate | I37: United States | J37: Richardson | K37: Texas | L37: 75080 | M37: Central | N37: TEC-PH-10004977 | O37: Technology | P37: Phones | Q37: GE 30524EE4 | R37: 1097.544 | S37: 7 | T37: 0.2 | U37: 123.4737 | V37: =EOMONTH(C37,0) -> 42735 | W37: =YEAR(C37) -> 2016
A38: 37 | B38: CA-2016-117590 | C38: 42712 | D38: 42655 | E38: First Class | F38: GH-14485 | G38: Gene Hale | H38: Corporate | I38: United States | J38: Richardson | K38: Texas | L38: 75080 | M38: Central | N38: FUR-FU-10003664 | O38: Furniture | P38: Furnishings | Q38: Electrix Architect's Clamp-On Swing Arm Lamp, Black | R38: 190.92 | S38: 5 | T38: 0.6 | U38: -147.963 | V38: =EOMONTH(C38,0) -> 42735 | W38: =YEAR(C38) -> 2016
A39: 38 | B39: CA-2015-117415 | C39: 42365 | D39: 12/31/2015 | E39: Standard Class | F39: SN-20710 | G39: Steve Nguyen | H39: Home Office | I39: United States | J39: Houston | K39: Texas | L39: 77041 | M39: Central | N39: OFF-EN-10002986 | O39: Office Supplies | P39: Envelopes | Q39: #10-4 1/8" x 9 1/2" Premium Diagonal Seam Envelopes | R39: 113.328 | S39: 9 | T39: 0.2 | U39: 35.415 | V39: =EOMONTH(C39,0) -> 42369 | W39: =YEAR(C39) -> 2015
A40: 39 | B40: CA-2015-117415 | C40: 42365 | D40: 12/31/2015 | E40: Standard Class | F40: SN-20710 | G40: Steve Nguyen | H40: Home Office | I40: United States | J40: Houston | K40: Texas | L40: 77041 | M40: Central | N40: FUR-BO-10002545 | O40: Furniture | P40: Bookcases | Q40: Atlantic Metals Mobile 3-Shelf Bookcases, Custom Colors | R40: 532.3992 | S40: 3 | T40: 0.32 | U40: -46.9764 | V40: =EOMONTH(C40,0) -> 42369 | W40: =YEAR(C40) -> 2015
A41: 40 | B41: CA-2015-117415 | C41: 42365 | D41: 12/31/2015 | E41: Standard Class | F41: SN-20710 | G41: Steve Nguyen | H41: Home Office | I41: United States | J41: Houston | K41: Texas | L41: 77041 | M41: Central | N41: FUR-CH-10004218 | O41: Furniture | P41: Chairs | Q41: Global Fabric Manager's Chair, Dark Gray | R41: 212.058 | S41: 3 | T41: 0.3 | U41: -15.147 | V41: =EOMONTH(C41,0) -> 42369 | W41: =YEAR(C41) -> 2015
...

Sheet Dashboard

Sheet sales
A2: {=_xlfn.UNIQUE('[1]Sample - Superstore'!M2:M9995)} -> South | B2: =SUMIFS('Sample - Superstore'!R:R,'Sample - Superstore'!M:M,sales!A2) -> 391721.91 | D2: Row Labels | E2: Sum of Sales | F2: Region | G2: Sales | J2: {=_xlfn.UNIQUE('[1]Sample - Superstore'!V2:V9995)} -> 42704 | K2: =SUMIFS('Sample - Superstore'!R:R,'Sample - Superstore'!V:V,sales!J2) -> 79411.966 | P2: Row Labels | Q2: Sum of Sales | Z2: 2014 | AA2: =SUMIFS('Sample - Superstore'!U:U,'Sample - Superstore'!W:W,sales!Z2) -> 49543.974
A3: West | B3: =SUMIFS('Sample - Superstore'!R:R,'Sample - Superstore'!M:M,sales!A3) -> 725457.82 | D3: Central | E3: 501239.89 | F3: =D3 -> Central | G3: =E3 -> 501239.89 | J3: 42551 | K3: =SUMIFS('Sample - Superstore'!R:R,'Sample - Superstore'!V:V,sales!J3) -> 40344.534 | P3: 41670 | Q3: 14236.895 | R3: =P3 -> 41670 | S3: =Q3 -> 14236.895 | Z3: 2015 | AA3: =SUMIFS('Sample - Superstore'!U:U,'Sample - Superstore'!W:W,sales!Z3) -> 61618.604
A4: Central | B4: =SUMIFS('Sample - Superstore'!R:R,'Sample - Superstore'!M:M,sales!A4) -> 501239.89 | D4: East | E4: 678781.24 | F4: =D4 -> East | G4: =E4 -> 678781.24 | J4: 42308 | K4: =SUMIFS('Sample - Superstore'!R:R,'Sample - Superstore'!V:V,sales!J4) -> 31404.924 | P4: 41698 | Q4: 4519.892 | R4: =P4 -> 41698 | S4: =Q4 -> 4519.892 | Z4: 2016 | AA4: =SUMIFS('Sample - Superstore'!U:U,'Sample - Superstore'!W:W,sales!Z4) -> 81795.174
A5: East | B5: =SUMIFS('Sample - Superstore'!R:R,'Sample - Superstore'!M:M,sales!A5) -> 678781.24 | D5: South | E5: 391721.91 | F5: =D5 -> South | G5: =E5 -> 391721.91 | J5: 41820 | K5: =SUMIFS('Sample - Superstore'!R:R,'Sample - Superstore'!V:V,sales!J5) -> 34595.128 | P5: 41729 | Q5: 55691.009 | R5: =P5 -> 41729 | S5: =Q5 -> 55691.009 | Z5: 2017 | AA5: =SUMIFS('Sample - Superstore'!U:U,'Sample - Superstore'!W:W,sales!Z5) -> 93439.27
D6: West | E6: 725457.82 | F6: =D6 -> West | G6: =E6 -> 725457.82 | J6: 42855 | K6: =SUMIFS('Sample - Superstore'!R:R,'Sample - Superstore'!V:V,sales!J6) -> 36521.536 | P6: 41759 | Q6: 28295.345 | R6: =P6 -> 41759 | S6: =Q6 -> 28295.345
D7: Grand Total | E7: 2297200.9 | F7: =D7 -> Grand Total | G7: =E7 -> 2297200.9 | J7: 42735 | K7: =SUMIFS('Sample - Superstore'!R:R,'Sample - Superstore'!V:V,sales!J7) -> 96999.043 | P7: 41790 | Q7: 23648.287 | R7: =P7 -> 41790 | S7: =Q7 -> 23648.287
J8: 42338 | K8: =SUMIFS('Sample - Superstore'!R:R,'Sample - Superstore'!V:V,sales!J8) -> 75972.564 | P8: 41820 | Q8: 34595.128 | R8: =P8 -> 41820 | S8: =Q8 -> 34595.128 | Z8: {=_xlfn.UNIQUE('Sample - Superstore'!M:M)} -> Region | AA8: profit sum
J9: 41973 | K9: =SUMIFS('Sample - Superstore'!R:R,'Sample - Superstore'!V:V,sales!J9) -> 78628.717 | P9: 41851 | Q9: 33946.393 | R9: =P9 -> 41851 | S9: =Q9 -> 33946.393 | Z9: South | AA9: =SUMIFS('Sample - Superstore'!U:U,'Sample - Superstore'!M:M,sales!Z9) -> 46749.43 | AF9: Row Labels | AG9: Sum of Profit | AI9: Region | AJ9: Total Profit
J10: 41790 | K10: =SUMIFS('Sample - Superstore'!R:R,'Sample - Superstore'!V:V,sales!J10) -> 23648.287 | P10: 41882 | Q10: 27909.468 | R10: =P10 -> 41882 | S10: =Q10 -> 27909.468 | Z10: West | AA10: =SUMIFS('Sample - Superstore'!U:U,'Sample - Superstore'!M:M,sales!Z10) -> 108418.45 | AF10: Central | AG10: 39706.362 | AI10: =AF10 -> Central | AJ10: =AG10 -> 39706.362
J11: 41882 | K11: =SUMIFS('Sample - Superstore'!R:R,'Sample - Superstore'!V:V,sales!J11) -> 27909.468 | P11: 41912 | Q11: 81777.351 | R11: =P11 -> 41912 | S11: =Q11 -> 81777.351 | Z11: Central | AA11: =SUMIFS('Sample - Superstore'!U:U,'Sample - Superstore'!M:M,sales!Z11) -> 39706.362 | AF11: East | AG11: 91522.78 | AI11: =AF11 -> East | AJ11: =AG11 -> 91522.78
J12: 42947 | K12: =SUMIFS('Sample - Superstore'!R:R,'Sample - Superstore'!V:V,sales!J12) -> 45264.416 | P12: 41943 | Q12: 31453.393 | R12: =P12 -> 41943 | S12: =Q12 -> 31453.393 | Z12: East | AA12: =SUMIFS('Sample - Superstore'!U:U,'Sample - Superstore'!M:M,sales!Z12) -> 91522.78 | AF12: South | AG12: 46749.43 | AI12: =AF12 -> South | AJ12: =AG12 -> 46749.43
J13: 42277 | K13: =SUMIFS('Sample - Superstore'!R:R,'Sample - Superstore'!V:V,sales!J13) -> 64595.918 | P13: 41973 | Q13: 78628.717 | R13: =P13 -> 41973 | S13: =Q13 -> 78628.717 | Z13: 0 | AA13: =SUMIFS('Sample - Superstore'!U:U,'Sample - Superstore'!M:M,sales!Z13) -> 0 | AF13: West | AG13: 108418.45 | AI13: =AF13 -> West | AJ13: =AG13 -> 108418.45
J14: 42400 | K14: =SUMIFS('Sample - Superstore'!R:R,'Sample - Superstore'!V:V,sales!J14) -> 18542.491 | P14: 42004 | Q14: 69545.62 | R14: =P14 -> 42004 | S14: =Q14 -> 69545.62 | AF14: Grand Total | AG14: 286397.02
J15: 43039 | K15: =SUMIFS('Sample - Superstore'!R:R,'Sample - Superstore'!V:V,sales!J15) -> 77776.923 | P15: 42035 | Q15: 18174.076 | R15: =P15 -> 42035 | S15: =Q15 -> 18174.076
J16: 42369 | K16: =SUMIFS('Sample - Superstore'!R:R,'Sample - Superstore'!V:V,sales!J16) -> 74919.521 | P16: 42063 | Q16: 11951.411 | R16: =P16 -> 42063 | S16: =Q16 -> 11951.411
J17: 43008 | K17: =SUMIFS('Sample - Superstore'!R:R,'Sample - Superstore'!V:V,sales!J17) -> 87866.652 | P17: 42094 | Q17: 38726.252 | R17: =P17 -> 42094 | S17: =Q17 -> 38726.252
J18: 42582 | K18: =SUMIFS('Sample - Superstore'!R:R,'Sample - Superstore'!V:V,sales!J18) -> 39261.963 | P18: 42124 | Q18: 34195.208 | R18: =P18 -> 42124 | S18: =Q18 -> 34195.208
J19: 42460 | K19: =SUMIFS('Sample - Superstore'!R:R,'Sample - Superstore'!V:V,sales!J19) -> 51715.875 | P19: 42155 | Q19: 30131.686 | R19: =P19 -> 42155 | S19: =Q19 -> 30131.686
J20: 41943 | K20: =SUMIFS('Sample - Superstore'!R:R,'Sample - Superstore'!V:V,sales!J20) -> 31453.393 | P20: 42185 | Q20: 24797.292 | R20: =P20 -> 42185 | S20: =Q20 -> 24797.292
J21: 42124 | K21: =SUMIFS('Sample - Superstore'!R:R,'Sample - Superstore'!V:V,sales!J21) -> 34195.208 | P21: 42216 | Q21: 28765.325 | R21: =P21 -> 42216 | S21: =Q21 -> 28765.325
J22: 42004 | K22: =SUMIFS('Sample - Superstore'!R:R,'Sample - Superstore'!V:V,sales!J22) -> 69545.62 | P22: 42247 | Q22: 36898.332 | R22: =P22 -> 42247 | S22: =Q22 -> 36898.332
J23: 42643 | K23: =SUMIFS('Sample - Superstore'!R:R,'Sample - Superstore'!V:V,sales!J23) -> 73410.025 | P23: 42277 | Q23: 64595.918 | R23: =P23 -> 42277 | S23: =Q23 -> 64595.918
J24: 43100 | K24: =SUMIFS('Sample - Superstore'!R:R,'Sample - Superstore'!V:V,sales!J24) -> 83829.319 | P24: 42308 | Q24: 31404.924 | R24: =P24 -> 42308 | S24: =Q24 -> 31404.924
A25: Total Sales | C25: Sum of Profit | E25: Sum of Quantity | G25: =COUNTA(Table1[Order ID]) -> 9994 | J25: 43069 | K25: =SUMIFS('Sample - Superstore'!R:R,'Sample - Superstore'!V:V,sales!J25) -> 118447.83 | P25: 42338 | Q25: 75972.564 | R25: =P25 -> 42338 | S25: =Q25 -> 75972.564
A26: 2297200.9 | C26: 286397.02 | E26: 37873 | G26: =A26/G25 -> 229.858 | J26: 42886 | K26: =SUMIFS('Sample - Superstore'!R:R,'Sample - Superstore'!V:V,sales!J26) -> 44261.11 | N26: quantity range | O26: frequency | P26: 42369 | Q26: 74919.521 | R26: =P26 -> 42369 | S26: =Q26 -> 74919.521
J27: 42490 | K27: =SUMIFS('Sample - Superstore'!R:R,'Sample - Superstore'!V:V,sales!J27) -> 38750.039 | N27: 1-2 | O27: =COUNTIFS('Sample - Superstore'!R:R,">=1",'Sample - Superstore'!R:R,"<=2") -> 72 | P27: 42400 | Q27: 18542.491 | R27: =P27 -> 42400 | S27: =Q27 -> 18542.491
A28: Total Sales | C28: Total Profit | E28: Total Quantity | G28: Average Order Value | J28: 42035 | K28: =SUMIFS('Sample - Superstore'!R:R,'Sample - Superstore'!V:V,sales!J28) -> 18174.076 | N28: 3-5 | O28: =COUNTIFS('Sample - Superstore'!R:R,">=3",'Sample - Superstore'!R:R,"<=5") -> 297 | P28: 42429 | Q28: 22978.815 | R28: =P28 -> 42429 | S28: =Q28 -> 22978.815
A29: =TEXT(A26,"$#,###,.0k") -> $2,297.2k | C29: =TEXT(C26,"$#,###,.0k") -> $286.4k | D29: =TEXT(D26,"#,###") | E29: =TEXT(E26,"#,###") -> 37,873 | F29: =TEXT(F26,"#,###") | G29: =TEXT(G26,"#,###") -> 230 | J29: 42916 | K29: =SUMIFS('Sample - Superstore'!R:R,'Sample - Superstore'!V:V,sales!J29) -> 52981.726 | N29: 6-10 | O29: =COUNTIFS('Sample - Superstore'!R:R,">=6",'Sample - Superstore'!R:R,"<=10") -> 673 | P29: 42460 | Q29: 51715.875 | R29: =P29 -> 42460 | S29: =Q29 -> 51715.875
J30: 42613 | K30: =SUMIFS('Sample - Superstore'!R:R,'Sample - Superstore'!V:V,sales!J30) -> 31115.374 | N30: 11+ | O30: =COUNTIFS('Sample - Superstore'!R:R,">=11") -> 8459 | P30: 42490 | Q30: 38750.039 | R30: =P30 -> 42490 | S30: =Q30 -> 38750.039
J31: 42094 | K31: =SUMIFS('Sample - Superstore'!R:R,'Sample - Superstore'!V:V,sales!J31) -> 38726.252 | P31: 42521 | Q31: 56987.728 | R31: =P31 -> 42521 | S31: =Q31 -> 56987.728
J32: 41912 | K32: =SUMIFS('Sample - Superstore'!R:R,'Sample - Superstore'!V:V,sales!J32) -> 81777.351 | P32: 42551 | Q32: 40344.534 | R32: =P32 -> 42551 | S32: =Q32 -> 40344.534
J33: 42794 | K33: =SUMIFS('Sample - Superstore'!R:R,'Sample - Superstore'!V:V,sales!J33) -> 20301.133 | P33: 42582 | Q33: 39261.963 | R33: =P33 -> 42582 | S33: =Q33 -> 39261.963
A34: Region | B34: (All) | J34: 42674 | K34: =SUMIFS('Sample - Superstore'!R:R,'Sample - Superstore'!V:V,sales!J34) -> 59687.745 | P34: 42613 | Q34: 31115.374 | R34: =P34 -> 42613 | S34: =Q34 -> 31115.374
A35: Category | B35: (All) | J35: 42155 | K35: =SUMIFS('Sample - Superstore'!R:R,'Sample - Superstore'!V:V,sales!J35) -> 30131.686 | P35: 42643 | Q35: 73410.025 | R35: =P35 -> 42643 | S35: =Q35 -> 73410.025
J36: 41729 | K36: =SUMIFS('Sample - Superstore'!R:R,'Sample - Superstore'!V:V,sales!J36) -> 55691.009 | P36: 42674 | Q36: 59687.745 | R36: =P36 -> 42674 | S36: =Q36 -> 59687.745 | Z36: =N38 -> 0 | AA36: =O38 -> 66.900292
J37: 42521 | K37: =SUMIFS('Sample - Superstore'!R:R,'Sample - Superstore'!V:V,sales!J37) -> 56987.728 | N37: Row Labels | O37: Average of Profit | P37: 42704 | Q37: 79411.966 | R37: =P37 -> 42704 | S37: =Q37 -> 79411.966 | Z37: =N39 -> 0.1 | AA37: =O39 -> 96.055074
J38: 42063 | K38: =SUMIFS('Sample - Superstore'!R:R,'Sample - Superstore'!V:V,sales!J38) -> 11951.411 | N38: 0 | O38: 66.900292 | P38: 42735 | Q38: 96999.043 | R38: =P38 -> 42735 | S38: =Q38 -> 96999.043 | Z38: =N40 -> 0.15 | AA38: =O40 -> 27.288298
J39: 42247 | K39: =SUMIFS('Sample - Superstore'!R:R,'Sample - Superstore'!V:V,sales!J39) -> 36898.332 | N39: 0.1 | O39: 96.055074 | P39: 42766 | Q39: 43971.374 | R39: =P39 -> 42766 | S39: =Q39 -> 43971.374 | Z39: =N41 -> 0.2 | AA39: =O41 -> 24.702572
J40: 42216 | K40: =SUMIFS('Sample - Superstore'!R:R,'Sample - Superstore'!V:V,sales!J40) -> 28765.325 | N40: 0.15 | O40: 27.288298 | P40: 42794 | Q40: 20301.133 | R40: =P40 -> 42794 | S40: =Q40 -> 20301.133 | Z40: =N42 -> 0.3 | AA40: =O42 -> -45.679636
J41: 41851 | K41: =SUMIFS('Sample - Superstore'!R:R,'Sample - Superstore'!V:V,sales!J41) -> 33946.393 | N41: 0.2 | O41: 24.702572 | P41: 42825 | Q41: 58872.353 | R41: =P41 -> 42825 | S41: =Q41 -> 58872.353 | Z41: =N43 -> 0.32 | AA41: =O43 -> -88.560656
...

Sheet year wise sales
L4: region
L5: {=_xlfn.UNIQUE('Sample - Superstore'!M2:M9995)} -> South
L6: West
B7: region | C7: West | L7: Central
L8: East
B10: Order Year | C10: Furniture | D10: Office Supplies | E10: Technology
B11: {=_xlfn.UNIQUE('Sample - Superstore'!W2:W9995)} -> 2016 | C11: =SUMIFS('Sample - Superstore'!$R$2:$R$9995,'Sample - Superstore'!$W$2:$W$9995,'year wise sales'!$B11,'Sample - Superstore'!$O$2:$O$9995,'year wise sales'!C$10,'Sample - Superstore'!$M$2:$M$9995,'year wise sales'!$C$7) -> 73819.64 | D11: =SUMIFS('Sample - Superstore'!$R$2:$R$9995,'Sample - Superstore'!$W$2:$W$9995,'year wise sales'!$B11,'Sample - Superstore'!$O$2:$O$9995,'year wise sales'!D$10,'Sample - Superstore'!$M$2:$M$9995,'year wise sales'!$C$7) -> 47679.357 | E11: =SUMIFS('Sample - Superstore'!$R$2:$R$9995,'Sample - Superstore'!$W$2:$W$9995,'year wise sales'!$B11,'Sample - Superstore'!$O$2:$O$9995,'year wise sales'!E$10,'Sample - Superstore'!$M$2:$M$9995,'year wise sales'!$C$7) -> 65981.179
B12: 2015 | C12: =SUMIFS('Sample - Superstore'!$R$2:$R$9995,'Sample - Superstore'!$W$2:$W$9995,'year wise sales'!$B12,'Sample - Superstore'!$O$2:$O$9995,'year wise sales'!C$10,'Sample - Superstore'!$M$2:$M$9995,'year wise sales'!$C$7) -> 57004.943 | D12: =SUMIFS('Sample - Superstore'!$R$2:$R$9995,'Sample - Superstore'!$W$2:$W$9995,'year wise sales'!$B12,'Sample - Superstore'!$O$2:$O$9995,'year wise sales'!D$10,'Sample - Superstore'!$M$2:$M$9995,'year wise sales'!$C$7) -> 37863.532 | E12: =SUMIFS('Sample - Superstore'!$R$2:$R$9995,'Sample - Superstore'!$W$2:$W$9995,'year wise sales'!$B12,'Sample - Superstore'!$O$2:$O$9995,'year wise sales'!E$10,'Sample - Superstore'!$M$2:$M$9995,'year wise sales'!$C$7) -> 45097.774
B13: 2014 | C13: =SUMIFS('Sample - Superstore'!$R$2:$R$9995,'Sample - Superstore'!$W$2:$W$9995,'year wise sales'!$B13,'Sample - Superstore'!$O$2:$O$9995,'year wise sales'!C$10,'Sample - Superstore'!$M$2:$M$9995,'year wise sales'!$C$7) -> 50082.448 | D13: =SUMIFS('Sample - Superstore'!$R$2:$R$9995,'Sample - Superstore'!$W$2:$W$9995,'year wise sales'!$B13,'Sample - Superstore'!$O$2:$O$9995,'year wise sales'!D$10,'Sample - Superstore'!$M$2:$M$9995,'year wise sales'!$C$7) -> 52846.854 | E13: =SUMIFS('Sample - Superstore'!$R$2:$R$9995,'Sample - Superstore'!$W$2:$W$9995,'year wise sales'!$B13,'Sample - Superstore'!$O$2:$O$9995,'year wise sales'!E$10,'Sample - Superstore'!$M$2:$M$9995,'year wise sales'!$C$7) -> 44953.731
B14: 2017 | C14: =SUMIFS('Sample - Superstore'!$R$2:$R$9995,'Sample - Superstore'!$W$2:$W$9995,'year wise sales'!$B14,'Sample - Superstore'!$O$2:$O$9995,'year wise sales'!C$10,'Sample - Superstore'!$M$2:$M$9995,'year wise sales'!$C$7) -> 71705.711 | D14: =SUMIFS('Sample - Superstore'!$R$2:$R$9995,'Sample - Superstore'!$W$2:$W$9995,'year wise sales'!$B14,'Sample - Superstore'!$O$2:$O$9995,'year wise sales'!D$10,'Sample - Superstore'!$M$2:$M$9995,'year wise sales'!$C$7) -> 82463.506 | E14: =SUMIFS('Sample - Superstore'!$R$2:$R$9995,'Sample - Superstore'!$W$2:$W$9995,'year wise sales'!$B14,'Sample - Superstore'!$O$2:$O$9995,'year wise sales'!E$10,'Sample - Superstore'!$M$2:$M$9995,'year wise sales'!$C$7) -> 95959.148
B27: Sum of Sales | C27: Column Labels
B28: Row Labels | C28: Furniture | D28: Office Supplies | E28: Technology | F28: Grand Total | H28: Order Year | I28: Furniture | J28: Office Supplies | K28: Technology
B29: 2014 | C29: 157192.85 | D29: 151776.41 | E29: 175278.23 | F29: 484247.5 | H29: =B29 -> 2014 | I29: =C29 -> 157192.85 | J29: =D29 -> 151776.41 | K29: =E29 -> 175278.23
B30: 2015 | C30: 170518.24 | D30: 137233.46 | E30: 162780.81 | F30: 470532.51 | H30: =B30 -> 2015 | I30: =C30 -> 170518.24 | J30: =D30 -> 137233.46 | K30: =E30 -> 162780.81
B31: 2016 | C31: 198901.44 | D31: 183939.98 | E31: 226364.18 | F31: 609205.6 | H31: =B31 -> 2016 | I31: =C31 -> 198901.44 | J31: =D31 -> 183939.98 | K31: =E31 -> 226364.18
B32: 2017 | C32: 215471.24 | D32: 246097.18 | E32: 271646.84 | F32: 733215.26 | H32: =B32 -> 2017 | I32: =C32 -> 215471.24 | J32: =D32 -> 246097.18 | K32: =E32 -> 271646.84
B33: Grand Total | C33: 742083.77 | D33: 719047.03 | E33: 836070.06 | F33: 2297200.9

Sheet Detail1
A1: Details for Average of Sales2 - order month: 3/31/2014, order year: 2014 (+)
A3: Row ID | B3: Order ID | C3: Order Date | D3: Ship Date | E3: Ship Mode | F3: Customer ID | G3: Customer Name | H3: Segment | I3: Country | J3: City | K3: State | L3: Postal Code | M3: Region | N3: Product ID | O3: Category | P3: Sub-Category | Q3: Product Name | R3: Sales | S3: Quantity | T3: Discount | U3: Profit | V3: order month | W3: order year
A4: 9947 | B4: CA-2014-111157 | C4: 41700 | D4: 41793 | E4: Standard Class | F4: NH-18610 | G4: Nicole Hansen | H4: Corporate | I4: United States | J4: Philadelphia | K4: Pennsylvania | L4: 19120 | M4: East | N4: TEC-AC-10004353 | O4: Technology | P4: Accessories | Q4: Hypercom P1300 Pinpad | R4: 151.2 | S4: 3 | T4: 0.2 | U4: 32.13 | V4: 41729 | W4: 2014
A5: 9946 | B5: CA-2014-111157 | C5: 41700 | D5: 41793 | E5: Standard Class | F5: NH-18610 | G5: Nicole Hansen | H5: Corporate | I5: United States | J5: Philadelphia | K5: Pennsylvania | L5: 19120 | M5: East | N5: OFF-PA-10000327 | O5: Office Supplies | P5: Paper | Q5: Xerox 1971 | R5: 3.424 | S5: 1 | T5: 0.2 | U5: 1.07 | V5: 41729 | W5: 2014
A6: 9900 | B6: US-2014-117380 | C6: 41726 | D6: 41702 | E6: Standard Class | F6: MP-18175 | G6: Mike Pelletier | H6: Home Office | I6: United States | J6: Springfield | K6: Ohio | L6: 45503 | M6: East | N6: FUR-TA-10000198 | O6: Furniture | P6: Tables | Q6: Chromcraft Bull-Nose Wood Oval Conference Tables & Bases | R6: 330.588 | S6: 1 | T6: 0.4 | U6: -143.2548 | V6: 41729 | W6: 2014
A7: 9660 | B7: CA-2014-100860 | C7: 41724 | D7: 3/30/2014 | E7: Second Class | F7: CS-12505 | G7: Cindy Stewart | H7: Consumer | I7: United States | J7: Pomona | K7: California | L7: 91767 | M7: West | N7: OFF-LA-10001982 | O7: Office Supplies | P7: Labels | Q7: Smead Alpha-Z Color-Coded Name Labels First Letter Starter Set | R7: 18.75 | S7: 5 | T7: 0 | U7: 9 | V7: 41729 | W7: 2014
A8: 9644 | B8: CA-2014-104563 | C8: 41705 | D8: 41976 | E8: Standard Class | F8: CM-12715 | G8: Craig Molinari | H8: Corporate | I8: United States | J8: Seattle | K8: Washington | L8: 98103 | M8: West | N8: FUR-CH-10004495 | O8: Furniture | P8: Chairs | Q8: Global Leather and Oak Executive Chair, Black | R8: 481.568 | S8: 2 | T8: 0.2 | U8: 54.1764 | V8: 41729 | W8: 2014
A9: 9643 | B9: CA-2014-104563 | C9: 41705 | D9: 41976 | E9: Standard Class | F9: CM-12715 | G9: Craig Molinari | H9: Corporate | I9: United States | J9: Seattle | K9: Washington | L9: 98103 | M9: West | N9: FUR-CH-10002780 | O9: Furniture | P9: Chairs | Q9: Office Star - Task Chair with Contemporary Loop Arms | R9: 436.704 | S9: 6 | T9: 0.2 | U9: 21.8352 | V9: 41729 | W9: 2014
A10: 9642 | B10: CA-2014-104563 | C10: 41705 | D10: 41976 | E10: Standard Class | F10: CM-12715 | G10: Craig Molinari | H10: Corporate | I10: United States | J10: Seattle | K10: Washington | L10: 98103 | M10: West | N10: OFF-ST-10000934 | O10: Office Supplies | P10: Storage | Q10: Contico 72"H Heavy-Duty Storage System | R10: 204.9 | S10: 5 | T10: 0 | U10: 0 | V10: 41729 | W10: 2014
A11: 9641 | B11: CA-2014-104563 | C11: 41705 | D11: 41976 | E11: Standard Class | F11: CM-12715 | G11: Craig Molinari | H11: Corporate | I11: United States | J11: Seattle | K11: Washington | L11: 98103 | M11: West | N11: OFF-AR-10000390 | O11: Office Supplies | P11: Art | Q11: Newell Chalk Holder | R11: 20.65 | S11: 5 | T11: 0 | U11: 9.499 | V11: 41729 | W11: 2014
A12: 9568 | B12: CA-2014-130428 | C12: 41729 | D12: 3/31/2014 | E12: Same Day | F12: TG-21640 | G12: Trudy Glocke | H12: Consumer | I12: United States | J12: Tampa | K12: Florida | L12: 33614 | M12: South | N12: OFF-AR-10004027 | O12: Office Supplies | P12: Art | Q12: Binney & Smith inkTank Erasable Desk Highlighter, Chisel Tip, Yellow, 12/Box | R12: 4.032 | S12: 2 | T12: 0.2 | U12: 1.0584 | V12: 41729 | W12: 2014
A13: 9567 | B13: CA-2014-130428 | C13: 41729 | D13: 3/31/2014 | E13: Same Day | F13: TG-21640 | G13: Trudy Glocke | H13: Consumer | I13: United States | J13: Tampa | K13: Florida | L13: 33614 | M13: South | N13: OFF-BI-10001636 | O13: Office Supplies | P13: Binders | Q13: Ibico Plastic and Wire Spiral Binding Combs | R13: 12.645 | S13: 5 | T13: 0.7 | U13: -10.116 | V13: 41729 | W13: 2014
A14: 9566 | B14: CA-2014-130428 | C14: 41729 | D14: 3/31/2014 | E14: Same Day | F14: TG-21640 | G14: Trudy Glocke | H14: Consumer | I14: United States | J14: Tampa | K14: Florida | L14: 33614 | M14: South | N14: FUR-CH-10002965 | O14: Furniture | P14: Chairs | Q14: Global Leather Highback Executive Chair with Pneumatic Height Adjustment, Black | R14: 1125.488 | S14: 7 | T14: 0.2 | U14: 98.4802 | V14: 41729 | W14: 2014
A15: 9515 | B15: CA-2014-100293 | C15: 41712 | D15: 3/18/2014 | E15: Standard Class | F15: NF-18475 | G15: Neil Franzˆsisch | H15: Home Office | I15: United States | J15: Jacksonville | K15: Florida | L15: 32216 | M15: South | N15: OFF-PA-10000176 | O15: Office Supplies | P15: Paper | Q15: Xerox 1887 | R15: 91.056 | S15: 6 | T15: 0.2 | U15: 31.8696 | V15: 41729 | W15: 2014
A16: 9407 | B16: CA-2014-152618 | C16: 41712 | D16: 3/17/2014 | E16: First Class | F16: RB-19465 | G16: Rick Bensley | H16: Home Office | I16: United States | J16: Chicago | K16: Illinois | L16: 60653 | M16: Central | N16: OFF-PA-10001215 | O16: Office Supplies | P16: Paper | Q16: Xerox 1963 | R16: 8.448 | S16: 2 | T16: 0.2 | U16: 2.64 | V16: 41729 | W16: 2014
A17: 9406 | B17: CA-2014-152618 | C17: 41712 | D17: 3/17/2014 | E17: First Class | F17: RB-19465 | G17: Rick Bensley | H17: Home Office | I17: United States | J17: Chicago | K17: Illinois | L17: 60653 | M17: Central | N17: TEC-MA-10003626 | O17: Technology | P17: Machines | Q17: Hewlett-Packard Deskjet 6540 Color Inkjet Printer | R17: 574.91 | S17: 2 | T17: 0.3 | U17: 156.047 | V17: 41729 | W17: 2014
A18: 9310 | B18: CA-2014-128237 | C18: 41723 | D18: 3/30/2014 | E18: Standard Class | F18: CA-12265 | G18: Christina Anderson | H18: Consumer | I18: United States | J18: San Francisco | K18: California | L18: 94110 | M18: West | N18: OFF-AR-10000034 | O18: Office Supplies | P18: Art | Q18: BIC Brite Liner Grip Highlighters, Assorted, 5/Pack | R18: 25.44 | S18: 6 | T18: 0 | U18: 9.9216 | V18: 41729 | W18: 2014
A19: 9309 | B19: CA-2014-128237 | C19: 41723 | D19: 3/30/2014 | E19: Standard Class | F19: CA-12265 | G19: Christina Anderson | H19: Consumer | I19: United States | J19: San Francisco | K19: California | L19: 94110 | M19: West | N19: TEC-AC-10002558 | O19: Technology | P19: Accessories | Q19: Imation†Swivel†Flash Drive†USB†flash drive†- 8 GB | R19: 45.48 | S19: 4 | T19: 0 | U19: 15.918 | V19: 41729 | W19: 2014
A20: 9308 | B20: CA-2014-128237 | C20: 41723 | D20: 3/30/2014 | E20: Standard Class | F20: CA-12265 | G20: Christina Anderson | H20: Consumer | I20: United States | J20: San Francisco | K20: California | L20: 94110 | M20: West | N20: OFF-AR-10003338 | O20: Office Supplies | P20: Art | Q20: Eberhard Faber 3 1/2" Golf Pencils | R20: 14.88 | S20: 2 | T20: 0 | U20: 3.72 | V20: 41729 | W20: 2014
A21: 9307 | B21: CA-2014-128237 | C21: 41723 | D21: 3/30/2014 | E21: Standard Class | F21: CA-12265 | G21: Christina Anderson | H21: Consumer | I21: United States | J21: San Francisco | K21: California | L21: 94110 | M21: West | N21: OFF-AR-10003829 | O21: Office Supplies | P21: Art | Q21: Newell 35 | R21: 6.56 | S21: 2 | T21: 0 | U21: 1.9024 | V21: 41729 | W21: 2014
A22: 9054 | B22: CA-2014-141838 | C22: 41724 | D22: 3/31/2014 | E22: Second Class | F22: DK-12835 | G22: Damala Kotsonis | H22: Corporate | I22: United States | J22: San Francisco | K22: California | L22: 94122 | M22: West | N22: TEC-PH-10004100 | O22: Technology | P22: Phones | Q22: Griffin GC17055 Auxiliary Audio Cable | R22: 28.784 | S22: 2 | T22: 0.2 | U22: 2.8784 | V22: 41729 | W22: 2014
A23: 9053 | B23: CA-2014-141838 | C23: 41724 | D23: 3/31/2014 | E23: Second Class | F23: DK-12835 | G23: Damala Kotsonis | H23: Corporate | I23: United States | J23: San Francisco | K23: California | L23: 94122 | M23: West | N23: OFF-BI-10003291 | O23: Office Supplies | P23: Binders | Q23: Wilson Jones Leather-Like Binders with DublLock Round Rings | R23: 27.936 | S23: 4 | T23: 0.2 | U23: 9.4284 | V23: 41729 | W23: 2014
A24: 9052 | B24: CA-2014-141838 | C24: 41724 | D24: 3/31/2014 | E24: Second Class | F24: DK-12835 | G24: Damala Kotsonis | H24: Corporate | I24: United States | J24: San Francisco | K24: California | L24: 94122 | M24: West | N24: OFF-AR-10004272 | O24: Office Supplies | P24: Art | Q24: Newell 308 | R24: 3.36 | S24: 2 | T24: 0 | U24: 0.84 | V24: 41729 | W24: 2014
A25: 8712 | B25: CA-2014-105648 | C25: 41701 | D25: 41823 | E25: Standard Class | F25: EJ-14155 | G25: Eva Jacobs | H25: Consumer | I25: United States | J25: San Diego | K25: California | L25: 92037 | M25: West | N25: FUR-TA-10002958 | O25: Furniture | P25: Tables | Q25: Bevis Oval Conference Table, Walnut | R25: 626.352 | S25: 3 | T25: 0.2 | U25: -23.4882 | V25: 41729 | W25: 2014
A26: 8501 | B26: CA-2014-169061 | C26: 41703 | D26: 41854 | E26: Second Class | F26: AB-10150 | G26: Aimee Bixby | H26: Consumer | I26: United States | J26: Yonkers | K26: New York | L26: 10701 | M26: East | N26: OFF-PA-10001878 | O26: Office Supplies | P26: Paper | Q26: Xerox 1891 | R26: 97.82 | S26: 2 | T26: 0 | U26: 45.9754 | V26: 41729 | W26: 2014
A27: 8500 | B27: CA-2014-169061 | C27: 41703 | D27: 41854 | E27: Second Class | F27: AB-10150 | G27: Aimee Bixby | H27: Consumer | I27: United States | J27: Yonkers | K27: New York | L27: 10701 | M27: East | N27: OFF-BI-10001617 | O27: Office Supplies | P27: Binders | Q27: GBC Wire Binding Combs | R27: 49.632 | S27: 6 | T27: 0.2 | U27: 16.7508 | V27: 41729 | W27: 2014
A28: 8499 | B28: CA-2014-169061 | C28: 41703 | D28: 41854 | E28: Second Class | F28: AB-10150 | G28: Aimee Bixby | H28: Consumer | I28: United States | J28: Yonkers | K28: New York | L28: 10701 | M28: East | N28: OFF-SU-10000381 | O28: Office Supplies | P28: Supplies | Q28: Acme Forged Steel Scissors with Black Enamel Handles | R28: 18.62 | S28: 2 | T28: 0 | U28: 5.3998 | V28: 41729 | W28: 2014
A29: 8498 | B29: CA-2014-169061 | C29: 41703 | D29: 41854 | E29: Second Class | F29: AB-10150 | G29: Aimee Bixby | H29: Consumer | I29: United States | J29: Yonkers | K29: New York | L29: 10701 | M29: East | N29: TEC-AC-10002001 | O29: Technology | P29: Accessories | Q29: Logitech Wireless Gaming Headset G930 | R29: 479.97 | S29: 3 | T29: 0 | U29: 177.5889 | V29: 41729 | W29: 2014
A30: 8497 | B30: CA-2014-169061 | C30: 41703 | D30: 41854 | E30: Second Class | F30: AB-10150 | G30: Aimee Bixby | H30: Consumer | I30: United States | J30: Yonkers | K30: New York | L30: 10701 | M30: East | N30: OFF-AR-10000588 | O30: Office Supplies | P30: Art | Q30: Newell 345 | R30: 59.52 | S30: 3 | T30: 0 | U30: 15.4752 | V30: 41729 | W30: 2014
A31: 8464 | B31: CA-2014-100881 | C31: 41726 | D31: 41643 | E31: Standard Class | F31: DR-12940 | G31: Daniel Raglin | H31: Home Office | I31: United States | J31: Albuquerque | K31: New Mexico | L31: 87105 | M31: West | N31: TEC-PH-10003273 | O31: Technology | P31: Phones | Q31: AT&T TR1909W | R31: 302.376 | S31: 3 | T31: 0.2 | U31: 22.6782 | V31: 41729 | W31: 2014
A32: 8431 | B32: US-2014-113124 | C32: 41728 | D32: 41763 | E32: Standard Class | F32: NC-18340 | G32: Nat Carroll | H32: Consumer | I32: United States | J32: Apple Valley | K32: Minnesota | L32: 55124 | M32: Central | N32: OFF-ST-10001511 | O32: Office Supplies | P32: Storage | Q32: Space Solutions Commercial Steel Shelving | R32: 129.3 | S32: 2 | T32: 0 | U32: 6.465 | V32: 41729 | W32: 2014
A33: 8346 | B33: US-2014-155544 | C33: 41719 | D33: 3/25/2014 | E33: Standard Class | F33: GM-14440 | G33: Gary McGarr | H33: Consumer | I33: United States | J33: Knoxville | K33: Tennessee | L33: 37918 | M33: South | N33: FUR-CH-10000422 | O33: Furniture | P33: Chairs | Q33: Global Highback Leather Tilter in Burgundy | R33: 218.376 | S33: 3 | T33: 0.2 | U33: -10.9188 | V33: 41729 | W33: 2014
A34: 8345 | B34: US-2014-155544 | C34: 41719 | D34: 3/25/2014 | E34: Standard Class | F34: GM-14440 | G34: Gary McGarr | H34: Consumer | I34: United States | J34: Knoxville | K34: Tennessee | L34: 37918 | M34: South | N34: FUR-FU-10001473 | O34: Furniture | P34: Furnishings | Q34: DAX Wood Document Frame | R34: 32.952 | S34: 3 | T34: 0.2 | U34: 6.5904 | V34: 41729 | W34: 2014
A35: 8344 | B35: US-2014-155544 | C35: 41719 | D35: 3/25/2014 | E35: Standard Class | F35: GM-14440 | G35: Gary McGarr | H35: Consumer | I35: United States | J35: Knoxville | K35: Tennessee | L35: 37918 | M35: South | N35: OFF-LA-10004544 | O35: Office Supplies | P35: Labels | Q35: Avery 505 | R35: 59.2 | S35: 5 | T35: 0.2 | U35: 22.2 | V35: 41729 | W35: 2014
A36: 8311 | B36: CA-2014-168312 | C36: 41699 | D36: 41823 | E36: Standard Class | F36: GW-14605 | G36: Giulietta Weimer | H36: Consumer | I36: United States | J36: Houston | K36: Texas | L36: 77036 | M36: Central | N36: FUR-TA-10001866 | O36: Furniture | P36: Tables | Q36: Bevis Round Conference Room Tables and Bases | R36: 376.509 | S36: 3 | T36: 0.3 | U36: -43.0296 | V36: 41729 | W36: 2014
A37: 8310 | B37: CA-2014-168312 | C37: 41699 | D37: 41823 | E37: Standard Class | F37: GW-14605 | G37: Giulietta Weimer | H37: Consumer | I37: United States | J37: Houston | K37: Texas | L37: 77036 | M37: Central | N37: OFF-ST-10003692 | O37: Office Supplies | P37: Storage | Q37: Recycled Steel Personal File for Hanging File Folders | R37: 137.352 | S37: 3 | T37: 0.2 | U37: 8.5845 | V37: 41729 | W37: 2014
A38: 8300 | B38: US-2014-103338 | C38: 41709 | D38: 3/15/2014 | E38: Standard Class | F38: RB-19435 | G38: Richard Bierner | H38: Consumer | I38: United States | J38: Roseville | K38: California | L38: 95661 | M38: West | N38: OFF-AR-10001770 | O38: Office Supplies | P38: Art | Q38: Economy #2 Pencils | R38: 7.98 | S38: 3 | T38: 0 | U38: 2.0748 | V38: 41729 | W38: 2014
A39: 8011 | B39: CA-2014-127859 | C39: 41715 | D39: 3/20/2014 | E39: Second Class | F39: QJ-19255 | G39: Quincy Jones | H39: Corporate | I39: United States | J39: Philadelphia | K39: Pennsylvania | L39: 19134 | M39: East | N39: OFF-PA-10003641 | O39: Office Supplies | P39: Paper | Q39: Xerox 1909 | R39: 126.624 | S39: 6 | T39: 0.2 | U39: 41.1528 | V39: 41729 | W39: 2014
A40: 7951 | B40: CA-2014-131009 | C40: 41699 | D40: 41762 | E40: Standard Class | F40: SC-20380 | G40: Shahid Collister | H40: Consumer | I40: United States | J40: El Paso | K40: Texas | L40: 79907 | M40: Central | N40: OFF-ST-10001469 | O40: Office Supplies | P40: Storage | Q40: Fellowes Bankers Box Recycled Super Stor/Drawer | R40: 129.552 | S40: 3 | T40: 0.2 | U40: -22.6716 | V40: 41729 | W40: 2014
A41: 7950 | B41: CA-2014-131009 | C41: 41699 | D41: 41762 | E41: Standard Class | F41: SC-20380 | G41: Shahid Collister | H41: Consumer | I41: United States | J41: El Paso | K41: Texas | L41: 79907 | M41: Central | N41: FUR-FU-10001095 | O41: Furniture | P41: Furnishings | Q41: DAX Black Cherry Wood-Tone Poster Frame | R41: 63.552 | S41: 6 | T41: 0.6 | U41: -34.9536 | V41: 41729 | W41: 2014
...

Sheet Sheet6
A1: order year | B1: (All)
A3: Row Labels | B3: Sum of Sales | C3: Average of Sales2
A4: 41670 | B4: 14236.895 | C4: 180.21386
A5: 41698 | B5: 4519.892 | C5: 98.258522
A6: 41729 | B6: 55691.009 | C6: 354.7198 | E6: sum of sales(first 6 months) | F6: =SUM(OFFSET(B3,COUNT(B:B),0,6)) -> 2297200.9
A7: 41759 | B7: 28295.345 | C7: 209.59515 | E7: Average sales (first 6 months) | F7: =AVERAGE(OFFSET(C3,COUNT(C:C),0,6)) -> 229.858
A8: 41790 | B8: 23648.287 | C8: 193.83842 | E8: sum of sales(last 6 months) | F8: =SUM(OFFSET(B3,COUNT(B:B),0,-6)) -> 2728242.5
A9: 41820 | B9: 34595.128 | C9: 256.2602 | E9: Average sales (last 6 months) | F9: =AVERAGE(OFFSET(C3,COUNT(C:C),0,-6)) -> 235.22256
A10: 41851 | B10: 33946.393 | C10: 237.38736
A11: 41882 | B11: 27909.468 | C11: 182.41483
A12: 41912 | B12: 81777.351 | C12: 305.13937
A13: 41943 | B13: 31453.393 | C13: 197.82008
A14: 41973 | B14: 78628.717 | C14: 247.26012
A15: 42004 | B15: 69545.62 | C15: 250.1641
A16: 42035 | B16: 18174.076 | C16: 313.34613
A17: 42063 | B17: 11951.411 | C17: 186.7408
A18: 42094 | B18: 38726.252 | C18: 280.62501
A19: 42124 | B19: 34195.208 | C19: 213.72005
A20: 42155 | B20: 30131.686 | C20: 206.38141
A21: 42185 | B21: 24797.292 | C21: 179.69052
... A51: 43100 | B51: 83829.319 | C51: 181.44874
A52: Grand Total | B52: 2297200.9 | C52: 229.858

Sheet sales and profit by segment
O3: Row Labels | P3: Sum of Profit | R3: year | S3: profit
O4: 2014 | P4: 49543.974 | R4: =O4 -> 2014 | S4: =P4 -> 49543.974
O5: 2015 | P5: 61618.604 | R5: =O5 -> 2015 | S5: =P5 -> 61618.604
O6: 2016 | P6: 81795.174 | R6: =O6 -> 2016 | S6: =P6 -> 81795.174
B7: segment | C7: sales | D7: profit | O7: 2017 | P7: 93439.27 | R7: =O7 -> 2017 | S7: =P7 -> 93439.27
B8: {=_xlfn.UNIQUE('Sample - Superstore'!H2:H9995)} -> Consumer | C8: =SUMIFS('Sample - Superstore'!$R$2:$R$9995,'Sample - Superstore'!$H$2:$H$9995,'sales and profit by segment'!B8) -> 1161401.3 | D8: =SUMIFS('Sample - Superstore'!$U$2:$U$9995,'Sample - Superstore'!$H$2:$H$9995,'sales and profit by segment'!B8) -> 134119.21 | O8: Grand Total | P8: 286397.02
B9: Corporate | C9: =SUMIFS('Sample - Superstore'!$R$2:$R$9995,'Sample - Superstore'!$H$2:$H$9995,'sales and profit by segment'!B9) -> 706146.37 | D9: =SUMIFS('Sample - Superstore'!$U$2:$U$9995,'Sample - Superstore'!$H$2:$H$9995,'sales and profit by segment'!B9) -> 91979.134
B10: Home Office | C10: =SUMIFS('Sample - Superstore'!$R$2:$R$9995,'Sample - Superstore'!$H$2:$H$9995,'sales and profit by segment'!B10) -> 429653.15 | D10: =SUMIFS('Sample - Superstore'!$U$2:$U$9995,'Sample - Superstore'!$H$2:$H$9995,'sales and profit by segment'!B10) -> 60298.679
B24: Row Labels | C24: Sum of Sales | D24: Sum of Profit | G24: Sales | H24: Profit
B25: Consumer | C25: 1161401.3 | D25: 134119.21 | F25: =B25 -> Consumer | G25: =C25 -> 1161401.3 | H25: =D25 -> 134119.21
B26: Corporate | C26: 706146.37 | D26: 91979.134 | F26: =B26 -> Corporate | G26: =C26 -> 706146.37 | H26: =D26 -> 91979.134
B27: Home Office | C27: 429653.15 | D27: 60298.679 | F27: =B27 -> Home Office | G27: =C27 -> 429653.15 | H27: =D27 -> 60298.679
B28: Grand Total | C28: 2297200.9 | D28: 286397.02

Sheet profit margin by sales subcateg
A2: subcategory | B2: sales | C2: profit | D2: profit margin
A3: {=_xlfn.UNIQUE('Sample - Superstore'!P2:P9995)} -> Bookcases | B3: =SUMIFS('Sample - Superstore'!$R$2:$R$9995,'Sample - Superstore'!$P$2:$P$9995,'profit margin by sales subcateg'!A3) -> 114880 | C3: =SUMIFS('Sample - Superstore'!$U$2:$U$9995,'Sample - Superstore'!$P$2:$P$9995,'profit margin by sales subcateg'!A3) -> -3472.556 | D3: =C3/B3 -> -0.030227682
A4: Chairs | B4: =SUMIFS('Sample - Superstore'!$R$2:$R$9995,'Sample - Superstore'!$P$2:$P$9995,'profit margin by sales subcateg'!A4) -> 328449.1 | C4: =SUMIFS('Sample - Superstore'!$U$2:$U$9995,'Sample - Superstore'!$P$2:$P$9995,'profit margin by sales subcateg'!A4) -> 26590.166 | D4: =C4/B4 -> 0.080956733
A5: Labels | B5: =SUMIFS('Sample - Superstore'!$R$2:$R$9995,'Sample - Superstore'!$P$2:$P$9995,'profit margin by sales subcateg'!A5) -> 12486.312 | C5: =SUMIFS('Sample - Superstore'!$U$2:$U$9995,'Sample - Superstore'!$P$2:$P$9995,'profit margin by sales subcateg'!A5) -> 5546.254 | D5: =C5/B5 -> 0.44418672
A6: Tables | B6: =SUMIFS('Sample - Superstore'!$R$2:$R$9995,'Sample - Superstore'!$P$2:$P$9995,'profit margin by sales subcateg'!A6) -> 206965.53 | C6: =SUMIFS('Sample - Superstore'!$U$2:$U$9995,'Sample - Superstore'!$P$2:$P$9995,'profit margin by sales subcateg'!A6) -> -17725.481 | D6: =C6/B6 -> -0.085644604
A7: Storage | B7: =SUMIFS('Sample - Superstore'!$R$2:$R$9995,'Sample - Superstore'!$P$2:$P$9995,'profit margin by sales subcateg'!A7) -> 223843.61 | C7: =SUMIFS('Sample - Superstore'!$U$2:$U$9995,'Sample - Superstore'!$P$2:$P$9995,'profit margin by sales subcateg'!A7) -> 21278.826 | D7: =C7/B7 -> 0.09506113
A8: Furnishings | B8: =SUMIFS('Sample - Superstore'!$R$2:$R$9995,'Sample - Superstore'!$P$2:$P$9995,'profit margin by sales subcateg'!A8) -> 91705.164 | C8: =SUMIFS('Sample - Superstore'!$U$2:$U$9995,'Sample - Superstore'!$P$2:$P$9995,'profit margin by sales subcateg'!A8) -> 13059.144 | D8: =C8/B8 -> 0.14240358
A9: Art | B9: =SUMIFS('Sample - Superstore'!$R$2:$R$9995,'Sample - Superstore'!$P$2:$P$9995,'profit margin by sales subcateg'!A9) -> 27118.792 | C9: =SUMIFS('Sample - Superstore'!$U$2:$U$9995,'Sample - Superstore'!$P$2:$P$9995,'profit margin by sales subcateg'!A9) -> 6527.787 | D9: =C9/B9 -> 0.24071083
A10: Phones | B10: =SUMIFS('Sample - Superstore'!$R$2:$R$9995,'Sample - Superstore'!$P$2:$P$9995,'profit margin by sales subcateg'!A10) -> 330007.05 | C10: =SUMIFS('Sample - Superstore'!$U$2:$U$9995,'Sample - Superstore'!$P$2:$P$9995,'profit margin by sales subcateg'!A10) -> 44515.731 | D10: =C10/B10 -> 0.13489327
A11: Binders | B11: =SUMIFS('Sample - Superstore'!$R$2:$R$9995,'Sample - Superstore'!$P$2:$P$9995,'profit margin by sales subcateg'!A11) -> 203412.73 | C11: =SUMIFS('Sample - Superstore'!$U$2:$U$9995,'Sample - Superstore'!$P$2:$P$9995,'profit margin by sales subcateg'!A11) -> 30221.763 | D11: =C11/B11 -> 0.14857361
A12: Appliances | B12: =SUMIFS('Sample - Superstore'!$R$2:$R$9995,'Sample - Superstore'!$P$2:$P$9995,'profit margin by sales subcateg'!A12) -> 107532.16 | C12: =SUMIFS('Sample - Superstore'!$U$2:$U$9995,'Sample - Superstore'!$P$2:$P$9995,'profit margin by sales subcateg'!A12) -> 18138.005 | D12: =C12/B12 -> 0.16867517
A13: Paper | B13: =SUMIFS('Sample - Superstore'!$R$2:$R$9995,'Sample - Superstore'!$P$2:$P$9995,'profit margin by sales subcateg'!A13) -> 78479.206 | C13: =SUMIFS('Sample - Superstore'!$U$2:$U$9995,'Sample - Superstore'!$P$2:$P$9995,'profit margin by sales subcateg'!A13) -> 34053.569 | D13: =C13/B13 -> 0.43391837
A14: Accessories | B14: =SUMIFS('Sample - Superstore'!$R$2:$R$9995,'Sample - Superstore'!$P$2:$P$9995,'profit margin by sales subcateg'!A14) -> 167380.32 | C14: =SUMIFS('Sample - Superstore'!$U$2:$U$9995,'Sample - Superstore'!$P$2:$P$9995,'profit margin by sales subcateg'!A14) -> 41936.636 | D14: =C14/B14 -> 0.250547
A15: Envelopes | B15: =SUMIFS('Sample - Superstore'!$R$2:$R$9995,'Sample - Superstore'!$P$2:$P$9995,'profit margin by sales subcateg'!A15) -> 16476.402 | C15: =SUMIFS('Sample - Superstore'!$U$2:$U$9995,'Sample - Superstore'!$P$2:$P$9995,'profit margin by sales subcateg'!A15) -> 6964.1767 | D15: =C15/B15 -> 0.42267582
... A19: Copiers | B19: =SUMIFS('Sample - Superstore'!$R$2:$R$9995,'Sample - Superstore'!$P$2:$P$9995,'profit margin by sales subcateg'!A19) -> 149528.03 | C19: =SUMIFS('Sample - Superstore'!$U$2:$U$9995,'Sample - Superstore'!$P$2:$P$9995,'profit margin by sales subcateg'!A19) -> 55617.825 | D19: =C19/B19 -> 0.37195585
A25: Row Labels | B25: Sum of Profit | C25: Sum of Sales | E25: subcategory | F25: sales | G25: profit | H25: profit margin
A26: Accessories | B26: 41936.636 | C26: 167380.32 | E26: =A26 -> Accessories | F26: =B26 -> 41936.636 | G26: =C26 -> 167380.32 | H26: =F26/G26 -> 0.250547
A27: Appliances | B27: 18138.005 | C27: 107532.16 | E27: =A27 -> Appliances | F27: =B27 -> 18138.005 | G27: =C27 -> 107532.16 | H27: =F27/G27 -> 0.16867517
A28: Art | B28: 6527.787 | C28: 27118.792 | E28: =A28 -> Art | F28: =B28 -> 6527.787 | G28: =C28 -> 27118.792 | H28: =F28/G28 -> 0.24071083
A29: Binders | B29: 30221.763 | C29: 203412.73 | E29: =A29 -> Binders | F29: =B29 -> 30221.763 | G29: =C29 -> 203412.73 | H29: =F29/G29 -> 0.14857361
A30: Bookcases | B30: -3472.556 | C30: 114880 | E30: =A30 -> Bookcases | F30: =B30 -> -3472.556 | G30: =C30 -> 114880 | H30: =F30/G30 -> -0.030227682
A31: Chairs | B31: 26590.166 | C31: 328449.1 | E31: =A31 -> Chairs | F31: =B31 -> 26590.166 | G31: =C31 -> 328449.1 | H31: =F31/G31 -> 0.080956733
A32: Copiers | B32: 55617.825 | C32: 149528.03 | E32: =A32 -> Copiers | F32: =B32 -> 55617.825 | G32: =C32 -> 149528.03 | H32: =F32/G32 -> 0.37195585
A33: Envelopes | B33: 6964.1767 | C33: 16476.402 | E33: =A33 -> Envelopes | F33: =B33 -> 6964.1767 | G33: =C33 -> 16476.402 | H33: =F33/G33 -> 0.42267582
A34: Fasteners | B34: 949.5182 | C34: 3024.28 | E34: =A34 -> Fasteners | F34: =B34 -> 949.5182 | G34: =C34 -> 3024.28 | H34: =F34/G34 -> 0.31396504
A35: Furnishings | B35: 13059.144 | C35: 91705.164 | E35: =A35 -> Furnishings | F35: =B35 -> 13059.144 | G35: =C35 -> 91705.164 | H35: =F35/G35 -> 0.14240358
A36: Labels | B36: 5546.254 | C36: 12486.312 | E36: =A36 -> Labels | F36: =B36 -> 5546.254 | G36: =C36 -> 12486.312 | H36: =F36/G36 -> 0.44418672
A37: Machines | B37: 3384.7569 | C37: 189238.63 | E37: =A37 -> Machines | F37: =B37 -> 3384.7569 | G37: =C37 -> 189238.63 | H37: =F37/G37 -> 0.017886184
... A42: Tables | B42: -17725.481 | C42: 206965.53 | E42: =A42 -> Tables | F42: =B42 -> -17725.481 | G42: =C42 -> 206965.53 | H42: =F42/G42 -> -0.085644604
A43: Grand Total | B43: 286397.02 | C43: 2297200.9
